[2024-06-16T00:55:51.876+0530] {local_task_job_runner.py:120} INFO - ::group::Pre task execution logs
[2024-06-16T00:55:51.913+0530] {taskinstance.py:2076} INFO - Dependencies all met for dep_context=non-requeueable deps ti=<TaskInstance: get_sqlite_data_send_s3.send_csv_s3 manual__2024-06-15T19:25:41.808263+00:00 [queued]>
[2024-06-16T00:55:51.931+0530] {taskinstance.py:2076} INFO - Dependencies all met for dep_context=requeueable deps ti=<TaskInstance: get_sqlite_data_send_s3.send_csv_s3 manual__2024-06-15T19:25:41.808263+00:00 [queued]>
[2024-06-16T00:55:51.931+0530] {taskinstance.py:2306} INFO - Starting attempt 1 of 1
[2024-06-16T00:55:51.971+0530] {taskinstance.py:2330} INFO - Executing <Task(PythonOperator): send_csv_s3> on 2024-06-15 19:25:41.808263+00:00
[2024-06-16T00:55:51.975+0530] {standard_task_runner.py:63} INFO - Started process 339134 to run task
[2024-06-16T00:55:51.981+0530] {standard_task_runner.py:90} INFO - Running: ['airflow', 'tasks', 'run', 'get_sqlite_data_send_s3', 'send_csv_s3', 'manual__2024-06-15T19:25:41.808263+00:00', '--job-id', '129', '--raw', '--subdir', 'DAGS_FOLDER/main.py', '--cfg-path', '/tmp/tmpt7v9cplv']
[2024-06-16T00:55:51.984+0530] {standard_task_runner.py:91} INFO - Job 129: Subtask send_csv_s3
[2024-06-16T00:55:52.068+0530] {task_command.py:426} INFO - Running <TaskInstance: get_sqlite_data_send_s3.send_csv_s3 manual__2024-06-15T19:25:41.808263+00:00 [running]> on host Mohammed-Raza.
[2024-06-16T00:55:52.201+0530] {taskinstance.py:2648} INFO - Exporting env vars: AIRFLOW_CTX_DAG_OWNER='airflow' AIRFLOW_CTX_DAG_ID='get_sqlite_data_send_s3' AIRFLOW_CTX_TASK_ID='send_csv_s3' AIRFLOW_CTX_EXECUTION_DATE='2024-06-15T19:25:41.808263+00:00' AIRFLOW_CTX_TRY_NUMBER='1' AIRFLOW_CTX_DAG_RUN_ID='manual__2024-06-15T19:25:41.808263+00:00'
[2024-06-16T00:55:52.201+0530] {taskinstance.py:430} INFO - ::endgroup::
[2024-06-16T00:55:54.001+0530] {taskinstance.py:441} INFO - ::group::Post task execution logs
[2024-06-16T00:55:54.002+0530] {taskinstance.py:2905} ERROR - Task failed with exception
Traceback (most recent call last):
  File "/home/mohdraza/.local/lib/python3.10/site-packages/boto3/s3/transfer.py", line 372, in upload_file
    future.result()
  File "/home/mohdraza/.local/lib/python3.10/site-packages/s3transfer/futures.py", line 103, in result
    return self._coordinator.result()
  File "/home/mohdraza/.local/lib/python3.10/site-packages/s3transfer/futures.py", line 266, in result
    raise self._exception
  File "/home/mohdraza/.local/lib/python3.10/site-packages/s3transfer/tasks.py", line 139, in __call__
    return self._execute_main(kwargs)
  File "/home/mohdraza/.local/lib/python3.10/site-packages/s3transfer/tasks.py", line 162, in _execute_main
    return_value = self._main(**kwargs)
  File "/home/mohdraza/.local/lib/python3.10/site-packages/s3transfer/upload.py", line 764, in _main
    client.put_object(Bucket=bucket, Key=key, Body=body, **extra_args)
  File "/home/mohdraza/.local/lib/python3.10/site-packages/botocore/client.py", line 565, in _api_call
    return self._make_api_call(operation_name, kwargs)
  File "/home/mohdraza/.local/lib/python3.10/site-packages/botocore/client.py", line 1021, in _make_api_call
    raise error_class(parsed_response, operation_name)
botocore.exceptions.ClientError: An error occurred (AccessDenied) when calling the PutObject operation: Access Denied

During handling of the above exception, another exception occurred:

Traceback (most recent call last):
  File "/home/mohdraza/.local/lib/python3.10/site-packages/airflow/models/taskinstance.py", line 465, in _execute_task
    result = _execute_callable(context=context, **execute_callable_kwargs)
  File "/home/mohdraza/.local/lib/python3.10/site-packages/airflow/models/taskinstance.py", line 432, in _execute_callable
    return execute_callable(context=context, **execute_callable_kwargs)
  File "/home/mohdraza/.local/lib/python3.10/site-packages/airflow/models/baseoperator.py", line 401, in wrapper
    return func(self, *args, **kwargs)
  File "/home/mohdraza/.local/lib/python3.10/site-packages/airflow/operators/python.py", line 235, in execute
    return_value = self.execute_callable()
  File "/home/mohdraza/.local/lib/python3.10/site-packages/airflow/operators/python.py", line 252, in execute_callable
    return self.python_callable(*self.op_args, **self.op_kwargs)
  File "/mnt/c/Users/mohdr/Documents/airflow/dags/main.py", line 158, in _send_csv_s3
    s3_client.upload_file(
  File "/home/mohdraza/.local/lib/python3.10/site-packages/boto3/s3/inject.py", line 145, in upload_file
    return transfer.upload_file(
  File "/home/mohdraza/.local/lib/python3.10/site-packages/boto3/s3/transfer.py", line 378, in upload_file
    raise S3UploadFailedError(
boto3.exceptions.S3UploadFailedError: Failed to upload /tmp/csv/data_university.csv to apache-airflow-bucket/data_university.csv: An error occurred (AccessDenied) when calling the PutObject operation: Access Denied
[2024-06-16T00:55:54.019+0530] {taskinstance.py:1206} INFO - Marking task as FAILED. dag_id=get_sqlite_data_send_s3, task_id=send_csv_s3, run_id=manual__2024-06-15T19:25:41.808263+00:00, execution_date=20240615T192541, start_date=20240615T192551, end_date=20240615T192554
[2024-06-16T00:55:54.063+0530] {standard_task_runner.py:110} ERROR - Failed to execute job 129 for task send_csv_s3 (Failed to upload /tmp/csv/data_university.csv to apache-airflow-bucket/data_university.csv: An error occurred (AccessDenied) when calling the PutObject operation: Access Denied; 339134)
[2024-06-16T00:55:54.091+0530] {local_task_job_runner.py:240} INFO - Task exited with return code 1
[2024-06-16T00:55:54.113+0530] {taskinstance.py:3503} INFO - 0 downstream tasks scheduled from follow-on schedule check
[2024-06-16T00:55:54.115+0530] {local_task_job_runner.py:222} INFO - ::endgroup::
