[2024-06-16T00:42:16.097+0530] {local_task_job_runner.py:120} INFO - ::group::Pre task execution logs
[2024-06-16T00:42:16.134+0530] {taskinstance.py:2076} INFO - Dependencies all met for dep_context=non-requeueable deps ti=<TaskInstance: get_sqlite_data_send_s3.send_csv_s3 manual__2024-06-15T19:11:17.454119+00:00 [queued]>
[2024-06-16T00:42:16.151+0530] {taskinstance.py:2076} INFO - Dependencies all met for dep_context=requeueable deps ti=<TaskInstance: get_sqlite_data_send_s3.send_csv_s3 manual__2024-06-15T19:11:17.454119+00:00 [queued]>
[2024-06-16T00:42:16.151+0530] {taskinstance.py:2306} INFO - Starting attempt 1 of 1
[2024-06-16T00:42:16.198+0530] {taskinstance.py:2330} INFO - Executing <Task(PythonOperator): send_csv_s3> on 2024-06-15 19:11:17.454119+00:00
[2024-06-16T00:42:16.203+0530] {standard_task_runner.py:63} INFO - Started process 335579 to run task
[2024-06-16T00:42:16.206+0530] {standard_task_runner.py:90} INFO - Running: ['airflow', 'tasks', 'run', 'get_sqlite_data_send_s3', 'send_csv_s3', 'manual__2024-06-15T19:11:17.454119+00:00', '--job-id', '106', '--raw', '--subdir', 'DAGS_FOLDER/main.py', '--cfg-path', '/tmp/tmpbsc4683_']
[2024-06-16T00:42:16.208+0530] {standard_task_runner.py:91} INFO - Job 106: Subtask send_csv_s3
[2024-06-16T00:42:16.306+0530] {task_command.py:426} INFO - Running <TaskInstance: get_sqlite_data_send_s3.send_csv_s3 manual__2024-06-15T19:11:17.454119+00:00 [running]> on host Mohammed-Raza.
[2024-06-16T00:42:16.457+0530] {taskinstance.py:2648} INFO - Exporting env vars: AIRFLOW_CTX_DAG_OWNER='airflow' AIRFLOW_CTX_DAG_ID='get_sqlite_data_send_s3' AIRFLOW_CTX_TASK_ID='send_csv_s3' AIRFLOW_CTX_EXECUTION_DATE='2024-06-15T19:11:17.454119+00:00' AIRFLOW_CTX_TRY_NUMBER='1' AIRFLOW_CTX_DAG_RUN_ID='manual__2024-06-15T19:11:17.454119+00:00'
[2024-06-16T00:42:16.457+0530] {taskinstance.py:430} INFO - ::endgroup::
[2024-06-16T00:42:16.471+0530] {taskinstance.py:441} INFO - ::group::Post task execution logs
[2024-06-16T00:42:16.471+0530] {taskinstance.py:2905} ERROR - Task failed with exception
Traceback (most recent call last):
  File "/home/mohdraza/.local/lib/python3.10/site-packages/airflow/models/taskinstance.py", line 465, in _execute_task
    result = _execute_callable(context=context, **execute_callable_kwargs)
  File "/home/mohdraza/.local/lib/python3.10/site-packages/airflow/models/taskinstance.py", line 432, in _execute_callable
    return execute_callable(context=context, **execute_callable_kwargs)
  File "/home/mohdraza/.local/lib/python3.10/site-packages/airflow/models/baseoperator.py", line 401, in wrapper
    return func(self, *args, **kwargs)
  File "/home/mohdraza/.local/lib/python3.10/site-packages/airflow/operators/python.py", line 235, in execute
    return_value = self.execute_callable()
  File "/home/mohdraza/.local/lib/python3.10/site-packages/airflow/operators/python.py", line 252, in execute_callable
    return self.python_callable(*self.op_args, **self.op_kwargs)
  File "/mnt/c/Users/mohdr/Documents/airflow/dags/main.py", line 148, in _send_csv_s3
    with open(CUR_DIR + "/configurations.json", "r") as output:
FileNotFoundError: [Errno 2] No such file or directory: '/mnt/c/Users/mohdr/Documents/airflow/dags/configurations.json'
[2024-06-16T00:42:16.488+0530] {taskinstance.py:1206} INFO - Marking task as FAILED. dag_id=get_sqlite_data_send_s3, task_id=send_csv_s3, run_id=manual__2024-06-15T19:11:17.454119+00:00, execution_date=20240615T191117, start_date=20240615T191216, end_date=20240615T191216
[2024-06-16T00:42:16.524+0530] {standard_task_runner.py:110} ERROR - Failed to execute job 106 for task send_csv_s3 ([Errno 2] No such file or directory: '/mnt/c/Users/mohdr/Documents/airflow/dags/configurations.json'; 335579)
[2024-06-16T00:42:16.541+0530] {local_task_job_runner.py:240} INFO - Task exited with return code 1
[2024-06-16T00:42:16.565+0530] {taskinstance.py:3503} INFO - 0 downstream tasks scheduled from follow-on schedule check
[2024-06-16T00:42:16.566+0530] {local_task_job_runner.py:222} INFO - ::endgroup::
